Workbook

Sheet 估值摘要
A1: 赤子城科技 (9911.HK) · 中报点评与估值锚定
A2: 基于2026年中期业绩(截至2026/6/30)｜单位US$mm除标注｜本页为输出摘要，明细见其余标签页
A4: 中性锚定价 (12个月) | C4: 悲观 | D4: 乐观 | E4: 当前价
A5: =估值与情景!C27 -> 11.80774 | C5: =估值与情景!B27 -> 8.529505 | D5: =估值与情景!D27 -> 15.085975 | E5: =假设与输入!$B$7 -> 9
C6: 下行保护 | D6: 重估弹性 | E6: ="上行 "&TEXT(估值与情景!C27/假设与输入!$B$7-1,"0.0%") -> 上行 31.2%
A9: 一、关键财务 (H1 2026)
A10: 指标 | B10: H1'26 | C10: H1'25 | D10: 同比 | E10: 评价
A11: 客户合约收入 | B11: =利润表!F7 -> 606.86 | C11: =利润表!E7 -> 442.845 | D11: =B11/C11-1 -> 0.37036661 | E11: 强劲，真实
A12: 毛利 | B12: =利润表!F9 -> 351.013 | C12: =利润表!E9 -> 247.104 | D12: =B12/C12-1 -> 0.42050715 | E12: 毛利率升至57.8%
A13: 经营利润(报告) | B13: =利润表!F18 -> 88.965 | C13: =利润表!E18 -> 66.732 | D13: =B13/C13-1 -> 0.33316849 | E13: 含出售收益
A14: 报告归母 | B14: =利润表!F27 -> 99.328 | C14: =利润表!E27 -> 68.11 | D14: =B14/C14-1 -> 0.45834679 | E14: 表观亮眼
A15: 核心经调整归母 | B15: =利润表!F35 -> 71.14794 | C15: =利润表!E35 -> 85.05484 | D15: =B15/C15-1 -> -0.1635051 | E15: 真实承压↓
A16: 经营活动现金流* | B16: 89.3 | C16: 73.5 | D16: =B16/C16-1 -> 0.21496599 | E16: 现金质量好
A17: *经营现金流为公告值(未并入公式)
A19: 二、估值锚定要点
A20: • 结论：中报「表观高增、核心承压」。收入+37%、毛利率提升是真增长；但归母+45.8%里约3,970万美元为出售子公司一次性收益，剔除后核心经调整利润同比约−16%。
A21: • 锚定口径：以「核心经调整归母」(剔除出售+重估)为估值基准，避免被一次性收益抬高。三法(FY26/FY27 P/E + FY27 EV/EBITDA)交叉取平均。
A22: • 净现金护城河：约4.97亿美元净现金≈每股HK$2.9，占当前市值约1/3，构成下行保护；扣现金后主业估值不贵(EV/核心EBITDA约6x)。
A23: • 上行催化：港股通带来的流动性/估值重估、短剧(Playlet)与精品游戏放量、买量投放后续转化为核心利润。
A24: • 下行风险：营销费率持续高企侵蚀利润、MENA地区集中度与地缘风险、一次性收益不可持续、创新业务毛利率下滑。
A25: • 与卖方对照：本模型中性锚定略低于市场中枢(约HK$13.5)，因对盈利质量给予更审慎折让。
A27: 免责声明：本文为基于公开信息的分析框架，非投资建议。作者非持牌投资顾问；股价、汇率、股数请以实时数据为准，模型假设(蓝字/黄底)可自行调整。

Sheet 利润表
A1: 赤子城科技 (9911.HK) — 合并利润表：历史与预测
A2: 单位：百万美元｜FY2023–25年为人民币口径按约7.15折美元(近似)，H1为公告美元实际值，E=预测(公式)
A4: 利润表 (US$mm) | B4: FY2023 | C4: FY2024 | D4: FY2025 | E4: H1'25 | F4: H1'26 | G4: FY2026E | H4: FY2027E | I4: FY2028E
A5: 社交业务收入 | B5: 409.5 | C5: 647.6 | D5: 858.7 | E5: 394.551 | F5: 538.684 | G5: =D5*(1+假设与输入!B13) -> 1150.658 | H5: =G5*(1+假设与输入!C13) -> 1403.8028 | I5: =H5*(1+假设与输入!D13) -> 1684.5633
A6: 创新业务收入 | B6: 53.1 | C6: 64.3 | D6: 104.9 | E6: 48.294 | F6: 68.176 | G6: =D6*(1+假设与输入!B14) -> 150.007 | H6: =G6*(1+假设与输入!C14) -> 207.00966 | I6: =H6*(1+假设与输入!D14) -> 273.25275
A7: 客户合约收入 (总) | B7: =B5+B6 -> 462.6 | C7: =C5+C6 -> 711.9 | D7: =D5+D6 -> 963.6 | E7: =E5+E6 -> 442.845 | F7: =F5+F6 -> 606.86 | G7: =G5+G6 -> 1300.665 | H7: =H5+H6 -> 1610.8124 | I7: =I5+I6 -> 1957.8161
A8: 收入成本 Cost of revenue | B8: =-( B7-B9 ) -> -221.7 | C8: =-( C7-C9 ) -> -347.2 | D8: =-( D7-D9 ) -> -425.5 | E8: =-( E7-E9 ) -> -195.741 | F8: =-( F7-F9 ) -> -255.847 | G8: =-( G7-G9 ) -> -552.78263 | H8: =-( H7-H9 ) -> -692.64934 | I8: =-( I7-I9 ) -> -851.64999
A9: 毛利 Gross profit | B9: 240.9 | C9: 364.7 | D9: 538.1 | E9: 247.104 | F9: 351.013 | G9: =G7*假设与输入!B18 -> 747.88238 | H9: =H7*假设与输入!C18 -> 918.16308 | I9: =I7*假设与输入!D18 -> 1106.1661
A10: 毛利率 % | B10: =B9/B7 -> 0.52075227 | C10: =C9/C7 -> 0.51229105 | D10: =D9/D7 -> 0.55842673 | E10: =E9/E7 -> 0.55799207 | F10: =F9/F7 -> 0.57840853 | G10: =G9/G7 -> 0.575 | H10: =H9/H7 -> 0.57 | I10: =I9/I7 -> 0.565
A12: 销售及营销费用 S&M | B12: — | C12: — | D12: — | E12: -139.429 | F12: -228.637 | G12: =-G7*假设与输入!B19 -> -481.24605 | H12: =-H7*假设与输入!C19 -> -571.83841 | I12: =-I7*假设与输入!D19 -> -665.65746
A13: 研发费用 R&D | B13: — | C13: — | D13: — | E13: -23.329 | F13: -31.223 | G13: =-G7*假设与输入!B20 -> -65.03325 | H13: =-H7*假设与输入!C20 -> -80.540621 | I13: =-I7*假设与输入!D20 -> -97.890803
A14: 管理费用 G&A | B14: — | C14: — | D14: — | E14: -16.965 | F14: -20.729 | G14: =-G7*假设与输入!B21 -> -44.22261 | H14: =-H7*假设与输入!C21 -> -53.15681 | I14: =-I7*假设与输入!D21 -> -62.650114
A15: 其他经营净损益 Other (减值/其他) | B15: — | C15: — | D15: — | E15: -0.649 | F15: -11.324 | G15: =-G7*假设与输入!B22 -> -23.41197 | H15: =-H7*假设与输入!C22 -> -28.994624 | I15: =-I7*假设与输入!D22 -> -35.240689
A16: 核心经营利润 (剔除一次性) | B16: — | C16: — | D16: — | E16: =E9+E12+E13+E14+E15 -> 66.732 | F16: =F9+F12+F13+F14+F15 -> 59.1 | G16: =G9+G12+G13+G14+G15 -> 133.96849 | H16: =H9+H12+H13+H14+H15 -> 183.63262 | I16: =I9+I12+I13+I14+I15 -> 244.72701
A17: 出售附属公司收益 (一次性) | B17: — | C17: — | D17: — | E17: 0 | F17: 29.865 | G17: =假设与输入!B34 -> 29.9 | H17: 0 | I17: 0
A18: 经营利润 (报告) Operating profit | B18: — | C18: — | D18: — | E18: =E16+E17 -> 66.732 | F18: =F16+F17 -> 88.965 | G18: =G16+G17 -> 163.86849 | H18: =H16+H17 -> 183.63262 | I18: =I16+I17 -> 244.72701
A20: 净财务收入 Net finance income | B20: — | C20: — | D20: — | E20: 3.675 | F20: 5.449 | G20: =假设与输入!B26 -> 11 | H20: =假设与输入!C26 -> 13 | I20: =假设与输入!D26 -> 15
A21: 应占联营损益 Assoc. | B21: — | C21: — | D21: — | E21: 0.099 | F21: -4.186 | G21: =假设与输入!B27 -> -7 | H21: =假设与输入!C27 -> -3 | I21: =假设与输入!D27 -> 0
A22: 权益法重估收益 (一次性) | B22: — | C22: — | D22: — | E22: 0 | F22: 9.805 | G22: =假设与输入!B35 -> 9.8 | H22: 0 | I22: 0
A23: 除税前利润 Profit before tax | B23: — | C23: — | D23: — | E23: =E18+E20+E21+E22 -> 70.506 | F23: =F18+F20+F21+F22 -> 100.033 | G23: =G18+G20+G21+G22 -> 177.6685 | H23: =H18+H20+H21+H22 -> 193.63262 | I23: =I18+I20+I21+I22 -> 259.72701
A24: 所得税 Income tax | B24: — | C24: — | D24: — | E24: 0.061 | F24: -0.287 | G24: =-G23*假设与输入!B28 -> -3.5533699 | H24: =-H23*假设与输入!C28 -> -3.8726523 | I24: =-I23*假设与输入!D28 -> -5.1945402
A25: 期内利润 Net profit | B25: 106.4 | C25: 110.2 | D25: 134.8 | E25: =E23+E24 -> 70.567 | F25: =F23+F24 -> 99.746 | G25: =G23+G24 -> 174.11513 | H25: =H23+H24 -> 189.75996 | I25: =I23+I24 -> 254.53247
A26: 少数股东损益 NCI | B26: — | C26: — | D26: — | E26: -2.457 | F26: -0.418 | G26: =-G25*假设与输入!B29 -> -1.7411513 | H26: =-H25*假设与输入!C29 -> -1.8975996 | I26: =-I25*假设与输入!D29 -> -2.5453247
A27: 归母净利润 (报告) Attributable | B27: 71.7 | C27: 66.9 | D27: 130.1 | E27: =E25+E26 -> 68.11 | F27: =F25+F26 -> 99.328 | G27: =G25+G26 -> 172.37397 | H27: =H25+H26 -> 187.86236 | I27: =I25+I26 -> 251.98714
A29: 加: 股份薪酬 SBC | B29: — | C29: — | D29: — | E29: 17.116 | F29: 11.606 | G29: =假设与输入!B30 -> 24 | H29: =假设与输入!C30 -> 27 | I29: =假设与输入!D30 -> 29
A30: 加: 折旧摊销 D&A | B30: — | C30: — | D30: — | E30: 6.039 | F30: 10.543 | G30: =假设与输入!B31 -> 22 | H30: =假设与输入!C31 -> 25 | I30: =假设与输入!D31 -> 28
A31: 经调整EBITDA (报告) | B31: 94.4 | C31: 134.7 | D31: 169.2 | E31: =E18+E29+E30 -> 89.887 | F31: =F18+F29+F30 -> 111.114 | G31: =G18+G29+G30 -> 209.86849 | H31: =H18+H29+H30 -> 235.63262 | I31: =I18+I29+I30 -> 301.72701
A33: ══ 盈利质量调整 ══
A34: 核心归母净利润 (剔除全部一次性) | B34: — | C34: — | D34: — | E34: =E27-E17-E22 -> 68.11 | F34: =F27-F17-F22 -> 59.658 | G34: =G27-G17-G22 -> 132.67397 | H34: =H27-H17-H22 -> 187.86236 | I34: =I27-I17-I22 -> 251.98714
A35: 核心经调整归母 (核心+SBC) | B35: — | C35: — | D35: — | E35: =E34+E29*0.99 -> 85.05484 | F35: =F34+F29*0.99 -> 71.14794 | G35: =G34+G29*0.99 -> 156.43397 | H35: =H34+H29*0.99 -> 214.59236 | I35: =I34+I29*0.99 -> 280.69714
A36: 公司口径经调整归母 (+SBC−重估,含出售) | B36: 52.7 | C36: 81.5 | D36: 162.1 | E36: 85.111 | F36: 101.017 | G36: =G27+G29*0.99-G22 -> 186.33397 | H36: =H27+H29*0.99-H22 -> 214.59236 | I36: =I27+I29*0.99-I22 -> 280.69714
A37: 核心经调整EBITDA (剔除出售) | B37: — | C37: — | D37: — | E37: =E16+E29+E30 -> 89.887 | F37: =F16+F29+F30 -> 81.249 | G37: =G16+G29+G30 -> 179.96849 | H37: =H16+H29+H30 -> 235.63262 | I37: =I16+I29+I30 -> 301.72701
A39: 收入同比增速 | B39: — | C39: =C7/B7-1 -> 0.53891051 | D39: =D7/C7-1 -> 0.35356089 | E39: — | F39: =F7/E7-1 -> 0.37036661 | G39: =G7/D7-1 -> 0.34979763 | H39: =H7/G7-1 -> 0.23845296 | I39: =I7/H7-1 -> 0.21542151
A40: 报告归母同比增速 | B40: — | C40: =C27/B27-1 -> -0.066945607 | D40: =D27/C27-1 -> 0.94469357 | E40: — | F40: =F27/E27-1 -> 0.45834679 | G40: =G27/D27-1 -> 0.32493446 | H40: =H27/G27-1 -> 0.089853414 | I40: =I27/H27-1 -> 0.34133915
A41: 核心经调整归母同比增速 | B41: — | C41: — | D41: — | E41: — | F41: =F35/E35-1 -> -0.1635051 | G41: — | H41: =H35/G35-1 -> 0.37177596 | I41: =I35/H35-1 -> 0.30804814

Sheet 盈利质量
A1: 盈利质量拆解 · 2026年上半年 (US$mm)
A2: 从「报告归母」还原到「核心经调整」——揭示一次性收益对表观利润的贡献
A4: 项目 | B4: H1'25 | C4: H1'26 | D4: 同比
A5: 报告归母净利润 | B5: =利润表!E27 -> 68.11 | C5: =利润表!F27 -> 99.328 | D5: =C5/B5-1 -> 0.45834679
A6: 减：出售附属公司收益(一次性) | B6: =-利润表!E17 -> 0 | C6: =-利润表!F17 -> -29.865 | D6: —
A7: 减：权益法重估收益(一次性) | B7: =-利润表!E22 -> 0 | C7: =-利润表!F22 -> -9.805 | D7: —
A8: 核心归母净利润 (剔除一次性) | B8: =利润表!E34 -> 68.11 | C8: =利润表!F34 -> 59.658 | D8: =C8/B8-1 -> -0.12409338
A9: 加：股份薪酬 SBC (归属部分) | B9: =利润表!E29*0.99 -> 16.94484 | C9: =利润表!F29*0.99 -> 11.48994 | D9: =C9/B9-1 -> -0.32192101
A10: 核心经调整归母 | B10: =利润表!E35 -> 85.05484 | C10: =利润表!F35 -> 71.14794 | D10: =C10/B10-1 -> -0.1635051
A11: (备忘) 公司口径经调整归母 | B11: =利润表!E36 -> 85.111 | C11: =利润表!F36 -> 101.017 | D11: =C11/B11-1 -> 0.18688536
A13: 关键结论
A14: • 表观归母同比+45.8%，但其中约3,970万美元来自出售NADA、Ditto两项子公司的一次性收益(含重估)。
A15: • 剔除全部一次性后，「核心经调整归母」由H1'25约8,511万美元降至H1'26约7,115万美元，同比约−16%。
A16: • 主因：销售及营销费用同比+64%(占收入37.7%)，增幅超过毛利增量——公司在用全球买量换增长。
A17: • 现金质量仍稳健：经营活动现金流8,930万美元(+21%)，资本开支仅300万，一次性收益多为非经常但确有现金。
A18: • 因此表观高增需打折看待；真正决定估值的是营销投放能否在后续转化为可持续的核心利润。

Sheet 长期趋势
A1: 赤子城科技 — 5年趋势与盈利质量证据 (人民币千元，公司年报口径)
A2: 蓝字=年报实际值(来源:2025年报5年摘要表)｜黑字=计算比率｜关键:毛利率↑但EBITDA/净利率自2023见顶回落
A4: 损益 (RMB'000) | B4: 2021 | C4: 2022 | D4: 2023 | E4: 2024 | F4: 2025
A5: 客户合约收入 | B5: 2359816 | C5: 2799690 | D5: 3307799 | E5: 5091547 | F5: 6888850
A6: 毛利 | B6: 1003320 | C6: 1057907 | D6: 1722083 | E6: 2607667 | F6: 3847279
A7: 毛利率 % | B7: =B6/B5 -> 0.42516874 | C7: =C6/C5 -> 0.37786576 | D7: =D6/D5 -> 0.52061295 | E7: =E6/E5 -> 0.51215613 | F7: =F6/F5 -> 0.55847914
A8: 除所得税前利润 | B8: -393881 | C8: 287379 | D8: 772758 | E8: 784841 | F8: 955186
A9: 年内利润/(亏损) | B9: -387125 | C9: 287335 | D9: 760612 | E9: 787773 | F9: 963705
A10: 净利率 % | B10: =B9/B5 -> -0.16404881 | C10: =C9/C5 -> 0.10263101 | D10: =D9/D5 -> 0.22994505 | E10: =E9/E5 -> 0.15472174 | F10: =F9/F5 -> 0.13989345
A11: 经调整EBITDA | B11: 357067 | C11: 374688 | D11: 674638 | E11: 963144 | F11: 1214806
A12: 经调整EBITDA利润率 % | B12: =B11/B5 -> 0.15131137 | C12: =C11/C5 -> 0.13383196 | D12: =D11/D5 -> 0.20395375 | E12: =E11/E5 -> 0.1891653 | F12: =F11/F5 -> 0.1763438
A13: 本公司权益股东应占经调整利润 | B13: 85932 | C13: 168546 | D13: 377023 | E13: 582467 | F13: 1158748
A14: 收入同比 % | B14: — | C14: =C5/B5-1 -> 0.18640182 | D14: =D5/C5-1 -> 0.18148759 | E14: =E5/D5-1 -> 0.53925526 | F14: =F5/E5-1 -> 0.35299743
A15: 经调整归母同比 % | B15: — | C15: =C13/B13-1 -> 0.96138807 | D15: =D13/C13-1 -> 1.2369146 | E15: =E13/D13-1 -> 0.54491105 | F15: =F13/E13-1 -> 0.98937966
A17: 资产负债表 (RMB'000) | B17: 2021 | C17: 2022 | D17: 2023 | E17: 2024 | F17: 2025
A18: 资产总额 | B18: 1622428 | C18: 1720217 | D18: 2790856 | E18: 3582988 | F18: 4394178
A19: 负债总额 | B19: 782334 | C19: 482207 | D19: 843361 | E19: 1928103 | F19: 1819790
A20: 权益总额 | B20: 840094 | C20: 1238010 | D20: 1947495 | E20: 1654885 | F20: 2574388
A21: 资产负债率 % | B21: =B19/B18 -> 0.48219952 | C21: =C19/C18 -> 0.28031754 | D21: =D19/D18 -> 0.30218721 | E21: =E19/E18 -> 0.53812712 | F21: =F19/F18 -> 0.41413661
A23: 读图要点
A24: 1) 收入4年约2.9倍(CAGR约31%)——出海"爆款流水线"是真实资产。
A25: 2) 毛利率2022年38%→2025年56%持续上行(AI提效+高毛利UGC占比提升)。
A26: 3) 但净利率23%(2023)→14%(2025)、经调整EBITDA利润率20.4%→17.6%连降两年：S&M买量增速>毛利增速。
A27: 4) 2023净利率高点含蓝城兄弟并表约1.6亿一次性收益，清洗后回落更陡。
A28: 5) 头条"经调整归母"5年从0.86亿→11.59亿(+13倍)增长最快，因少数股东权益收缩+加回项放大，须与净利率趋势对照看。
A29: 6) 资产负债表持续走强：资产负债率48%(2021)→41%(2025)，净现金厚，构成下行安全垫。

Sheet SensorTower交叉验证
A1: Sensor Tower 交叉验证 (Newborn Town + MicroShowtime, 双平台)
A2: 数值为堆叠面积图估读(方向性可靠,非精确)｜期间Jan'25–Aug'26｜蓝字=估读输入,黑字=计算
A4: 一、买量效率 (月均,估读)
A5: 指标 | B5: H1'25 | C5: H2'25 | D5: H1'26 | E5: H1'26 vs H1'25 | F5: 口径
A6: 总下载量 (百万/月) | B6: 6.1 | C6: 8.6 | D6: 12.2 | E6: =D6/B6-1 -> 1 | F6: 图1/图4
A7: Store净收入 (百万美元/月) | B7: 8.8 | C7: 11.5 | D7: 12.8 | E7: =D7/B7-1 -> 0.45454545 | F7: 图2 (仅store内购)
A8: 单下载收入 (美元) | B8: =B7/B6 -> 1.442623 | C8: =C7/C6 -> 1.3372093 | D8: =D7/D6 -> 1.0491803 | E8: =D8/B8-1 -> -0.27272727 | F8: 收入/下载,越低越差
A9: (对照)报告总收入增速 | D9: =利润表!F7/利润表!E7-1 -> 0.37036661 | F9: 财报H1口径 +37%
A10: (对照)报告S&M增速 | D10: =利润表!F12/利润表!E12-1 -> 0.63980951 | F10: 财报 +64%;隐含CPI约−18%
A12: 二、口径量级差 (为何ST只是趋势代理)
A13: ST store净收入 H1'26 (估,6个月) | B13: =D7*6 -> 76.8 | C13: 结论:约87%收入在ST看不到的渠道(站外/网页充值/直播打赏直连+ST对第三方安卓/MENA低估)。→ST用于验证【增长趋势与获客效率】,不能作收入【绝对值】依据。
A14: 报告收入 H1'26 | B14: =利润表!F7 -> 606.86
A15: ST占报告收入比例 | B15: =B13/B14 -> 0.12655308
A17: 三、地域结构 (估读)
A18: 收入 Top 市场 (图3) | B18: 美国(第一,短剧驱动) > 沙特 > 土耳其 > 阿联酋 > 台湾/日本… ,「其他」最大→高度分散
A19: 下载 Top 市场 (图4) | B19: 土耳其/印度/埃及/巴基斯坦/印尼/伊拉克…新兴低ARPU市场为主
A20: 含义 | B20: 收入端分散、美国居首→MENA集中度风险低于市场担忧(利多);下载靠新兴市场→变现滞后,land-grab特征
A22: 四、对估值假设的影响
A23: • 买量效率下滑→已上调FY27/28营销费率(34%→35.5%、32%→34%),中性锚定相应下移(更审慎)。
A24: • 短剧(Playlet)在收入图中确成一块→创新业务成长有数据支撑,构成乐观期权。
A25: • 监控信号:若H2'26/H1'27收入增速加速追赶下载(翻倍)曲线=买量转投资(上修);若收入横住=跑步机(下修)。

Sheet 内部人DI时间线
A1: 赤子城科技 — 内部人/关联方 DI 权益披露时间线 (2024/11–2026/07)
A2: 数据来源:HKEX披露易DI申报｜(L)多头(S)空头｜代码:1101=市场增持,1113/1213=收购/转让,1711=董事持仓申报,1704=降至不再披露
A4: 相关日期 | B4: 申报人 | C4: 类别 | D4: 变动股数 | E4: 成交均价 | F4: 变动后持股 | G4: 占比% | H4: 解读
A5: 2024/11/08 | B5: TMF Trust | C5: ESOP信托 | D5: 526000 | E5: 3.7788 | F5: 71837833 | G5: 0.0603 | H5: 激励平台市场买入
A6: 2024/11/08 | B6: Three D Partners | C6: ESOP/RSU | D6: 526000 | E6: 3.7788 | F6: 61344403 | G6: 0.0514 | H6: 激励平台市场买入
A7: 2024/11/29 | B7: Phoenix (杜力系) | C7: 早期投资 | D7: -20458000 | E7: 3.7889 | F7: 59500948 | G7: 0.0499 | H7: 降至5%以下→部分减持*
A8: 2024/12/12 | B8: Three D Partners | C8: ESOP/RSU | D8: 500000 | E8: 3.9285 | F8: 71932403 | G8: 0.0603 | H8: 市场买入
A9: 2024/12/16 | B9: TMF Trust | C9: ESOP信托 | D9: 1010000 | E9: 3.9573 | F9: 83485833 | G9: 0.07 | H9: 市场买入
A10: 2024/12/23 | B10: 刘春河 Liu | C10: 创始人 | D10: — | E10: — | F10: 341828420 | G10: 0.2423 | H10: 董事申报(1711),持平
A11: 2024/12/23 | B11: 李平 Li Ping | C11: 创始人 | D11: — | E11: — | F11: 341828420 | G11: 0.2423 | H11: 董事申报(1711),持平
A12: 2024/12/23 | B12: Parallel World | C12: 创始人载体 | D12: — | E12: — | F12: 311828420 | G12: 0.221 | H12: 刘/李的持股载体
A13: 2024/12/23 | B13: Spriver Tech | C13: 创始人载体 | D13: — | E13: — | F13: 311828420 | G13: 0.221 | H13: 刘/李的持股载体
A14: 2024/12/23 | B14: 苏鉴 Su Jian | C14: 创始人 | D14: 150460810 | E14: 4.5 | F14: 159460810 | G14: 0.113 | H14: 米可重组@4.5(1113)
A15: 2024/12/23 | B15: JZZT/Travelspace/Ho Sheng | C15: 关联载体 | D15: 150460810 | E15: 4.5 | F15: 150460810 | G15: 0.1066 | H15: 米可重组@4.5(同一块)
A16: 2024/12/23 | B16: TMF Trust | C16: ESOP信托 | D16: 43321198 | E16: 4.5 | F16: 130795031 | G16: 0.0927 | H16: 重组获配
A17: 2024/12/23 | B17: Three D Partners | C17: ESOP/RSU | D17: 76980403 | E17: — | F17: 76980403 | G17: 0.0546 | H17: 重组获配
A18: 2025/01/06 | B18: Three D Partners | C18: ESOP/RSU | D18: 2344000 | E18: 3.4039 | F18: 84884403 | G18: 0.0602 | H18: 市场买入(低位)
A19: 2025/01/08 | B19: TMF Trust | C19: ESOP信托 | D19: 2354000 | E19: 3.3881 | F19: 143379031 | G19: 0.1016 | H19: 市场买入(低位)
A20: 2025/01/15 | B20: Three D Partners | C20: ESOP/RSU | D20: 2236000 | E20: 3.5661 | F20: 100888403 | G20: 0.0715 | H20: 市场买入
A21: 2025/01/16 | B21: TMF Trust | C21: ESOP信托 | D21: 2144000 | E21: 3.7253 | F21: 156847031 | G21: 0.1112 | H21: 市场买入
A22: 2025/04/09 | B22: Three D Partners | C22: ESOP/RSU | D22: 1916000 | E22: 4.82 | F22: 114288403 | G22: 0.081 | H22: 市场买入(加价)
A23: 2025/04/10 | B23: TMF Trust | C23: ESOP信托 | D23: 1834000 | E23: 5.32 | F23: 169937031 | G23: 0.1204 | H23: 市场买入(加价)
A24: 2025/06/23 | B24: JZZT Limited | C24: 关联载体 | D24: — | E24: — | F24: 150460810 | G24: 0.1065 | H24: 载体间转仓(Ho Sheng→JZZT)
A25: 2025/07/23 | B25: TMF Trust | C25: ESOP信托 | D25: 6897277 | E25: — | F25: 167495754 | G25: 0.1185 | H25: RSU相关转让(1213)
A26: 2025/07/25 | B26: TMF Trust | C26: ESOP信托 | D26: 14498167 | E26: — | F26: 152997587 | G26: 0.1083 | H26: RSU归属流出(净降)
A27: 2025/11/24 | B27: TMF Trust | C27: ESOP信托 | D27: 528000 | E27: 9.38 | F27: 155497702 | G27: 0.1101 | H27: 市场买入@9.38(最近成本)
A28: 2026/07/07 | B28: 李平 Li Ping | C28: 创始人 | D28: — | E28: — | F28: 341828420 | G28: 0.2436 | H28: 董事申报,持平(占比因回购微升)
A29: 2026/07/07 | B29: 刘春河 Liu | C29: 创始人 | D29: — | E29: — | F29: 341828420 | G29: 0.2436 | H29: 董事申报,持平
A30: 2026/07/07 | B30: 苏鉴 Su Jian | C30: 创始人 | D30: — | E30: — | F30: 159460810 | G30: 0.1137 | H30: 董事申报,持平
A31: 2026/07/07 | B31: 叶椿建 Ye | C31: 董事 | D31: — | E31: — | F31: 6000000 | G31: 0.0043 | H31: 新增董事申报
A32: 2026/07/22 | B32: TMF Trust | C32: ESOP信托 | D32: 18717049 | E32: — | F32: 140948269 | G32: 0.1005 | H32: RSU相关(1213)
A33: 2026/07/22 | B33: Three D Partners | C33: ESOP/RSU | D33: 11677825 | E33: — | F33: 111067301 | G33: 0.0792 | H33: RSU相关(1213)
A34: 2026/07/23 | B34: JZZT Limited | C34: 关联+衍生 | D34: 12000000 | E34: — | F34: 150460810 | G34: 0.1072 | H34: 另建0.86%空头/借券(S)
A36: 读表结论
A37: ① 创始人零买卖:刘春河/李平各24.36%、苏鉴11.37%,两年纹丝不动(占比微升仅因回购缩分母)。无一人减持——最强的一条'没人跑'信号。
A38: ② 唯一持续买家是ESOP/RSU平台(TMF Trust+Three D),从HK$3.39一路买到9.38。这是'公司体系为员工归属买入',属技术性托底,不等于'创始人自掏腰包看好'。
A39: ③ ESOP平台密集建仓在HK$3.4–5.3(2024末–2025初),最近一次市场买入是2025/11 @HK$9.38——这是内部体系认可的最近成本,现价~9刚好在其下方。
A40: ④ 唯一的减持痕迹是早期投资Phoenix(杜力系)一只载体降到4.99%;但杜力系整体仍持约8.9%,属载体层面调整,非清仓。
A41: ⑤ 2026/07 JZZT另建0.86%空头(借券),金额小,多为对冲/结构性安排,非看空基本面。
A42: ★ 综合:内部人结构=创始人锁死+ESOP持续买入托底+早期资金边际微调,无实质派发。这是偏正面的所有权信号,但别把ESOP买入误读成创始人增持。
...

Sheet 持股结构演变
A1: 赤子城科技 — 持股结构 1年演变 (2025/08 → 2026/08)
A2: 持股量(股)｜蓝字=快照实际｜黑字=公式｜关键:2025两列无南向线(入通前),2026/3入通后南向从0→11%
A4: 参与者 | B4: 类型 | C4: 2025/08/27 | D4: 2025/12/31 | E4: 2026/08/26 | F4: 占比 now | G4: 1年变动(股) | H4: 解读
A5: 汇丰 HSBC | B5: 托管 | C5: 208136723 | D5: 376955336 | E5: 295507090 | F5: =E5/1401000000 -> 0.21092583 | G5: =E5-C5 -> 87370367 | H5: 年末曾冲26.7%(入通/年末托管集中)后回落
A6: 富途 Futu | B6: 散户 | C6: 200511505 | D6: 204759852 | E6: 198675496 | F6: =E6/1401000000 -> 0.14180978 | G6: =E6-C6 -> -1836009 | H6: 全年'焊死'在14%±,散户基数不增不减
A7: 摩根士丹利 MS | B7: 投行PB | C7: 162102879 | D7: 163596325 | E7: 156684015 | F7: =E7/1401000000 -> 0.11183727 | G7: =E7-C7 -> -5418864 | H7: 稳定~11.5%大块,疑似基金/swap
A8: 中金 CICC | B8: 中资投行 | C8: 162206596 | D8: 159206420 | E8: 152102420 | F8: =E8/1401000000 -> 0.10856704 | G8: =E8-C8 -> -10104176 | H8: 核心锁仓,全年小幅回落仍锁死
A9: 花旗 Citi | B9: 托管 | C9: 138527303 | D9: 141156585 | E9: 91950242 | F9: =E9/1401000000 -> 0.065631864 | G9: =E9-C9 -> -46577061 | H9: 全年净减~4700万→西方托管在撤
A10: 高盛 GS | B10: 投行PB | C10: 110097260 | D10: 108950592 | E10: 101521300 | F10: =E10/1401000000 -> 0.072463455 | G10: =E10-C10 -> -8575960 | H10: 核心锁仓,基本稳定
A11: 华泰 Huatai | B11: 中资券商 | C11: 48435198 | D11: 41199032 | E11: 44831454 | F11: =E11/1401000000 -> 0.03199961 | G11: =E11-C11 -> -3603744 | H11: 波动,无趋势
A12: 中银香港 | B12: 托管 | C12: 39160140 | D12: 36478140 | E12: 34126140 | F12: =E12/1401000000 -> 0.024358415 | G12: =E12-C12 -> -5034000 | H12: 缓降
A13: UBS | B13: 投行PB | C13: 18506098 | D13: 11974886 | E13: 5477776 | F13: =E13/1401000000 -> 0.0039099044 | G13: =E13-C13 -> -13028322 | H13: 全年从1850万一路减到550万→持续卖方
A14: 法巴 BNP | B14: 投行PB | C14: 15096459 | D14: 9175194 | E14: 7857704 | F14: =E14/1401000000 -> 0.0056086395 | G14: =E14-C14 -> -7238755 | H14: 持续减
A15: 盈透 IB | B15: 散户 | C15: 8001000 | D15: 10889000 | E15: 5589451 | F15: =E15/1401000000 -> 0.0039896153 | G15: =E15-C15 -> -2411549 | H15: 散户,波动
A16: 南向 港股通 (A3+A4) | B16: 南向 | C16: 0 | D16: 0 | E16: 154450355 | F16: =E16/1401000000 -> 0.11024294 | G16: =E16-C16 -> 154450355 | H16: ★入通后从0→11%:全年最大结构变化,新增内地买盘~1.55亿股
A17: 已发行股份(约) | C17: 1412800000 | D17: 1413400000 | E17: 1401000000 | F17: 回购注销:14.13亿→14.01亿(−0.8%)
A19: 一年结构演变:三条主线
A20: ① 【买盘换血】过去一年最大的结构变化是:入通带来南向从0→11%(约1.55亿股全新内地买盘);与此同时西方托管在撤——花旗−4700万、UBS−1300万、法巴持续减。买家结构显著'内地化'。
A21: ② 【核心锁死】创始人/战略锁仓的中金、高盛、MS三条大线全年基本稳定(11%/7.7%/11.5%),约40–50%死筹一年没松动;富途(散户)全年焊死在14%。锁仓+稳定散户≈六成筹码一年未动。
A22: ③ 【关键背离】过去一年南向净买入约11%(1.55亿股),股价却从~14跌到~9。结论:这11%新买盘不是推涨力量,而是在【承接抛盘】——被年末HSBC那笔170万股异动的回吐、花旗/UBS的减持、以及早期获利盘消化掉了。'有资金流入≠会涨',这是最重要的一课:净流入被等量的派发吃掉了。
A23: ④ 含义:赤子城的边际定价权正从西方机构转向南向(内地),而南向更偏情绪/动量,叠加薄流通→未来波动会更依赖内地情绪,而非西方长线资金。这强化了'流动性/控盘风险'的判断。

Sheet CCASS每日追踪
A1: 赤子城 — CCASS 逐日追踪 8/22–9/9 (中报8/25盘后 · T+2口径 · 完整弧线)
A2: 10个快照｜蓝=实际｜黑=公式｜阶段:派发→衰竭→承接→买盘扩散
A4: 参与者 | B4: 类型 | C4: 8/22 | D4: 8/24 | E4: 8/25 | F4: 8/26 | G4: 8/27 | H4: 8/29 | I4: 8/31 | J4: 9/3 | K4: 9/8 | L4: 9/9 | M4: 期间Δ | N4: 分类
A5: 汇丰 HSBC | B5: 托管 | C5: 286782680 | D5: 288854992 | E5: 295507090 | F5: 295507090 | G5: 293124713 | H5: 303980132 | I5: 301111043 | J5: 303954829 | K5: 303937260 | L5: 301296054 | M5: =L5-C5 -> 14513374 | N5: 活
A6: 富途 Futu | B6: 散户 | C6: 198789496 | D6: 198381496 | E6: 198675496 | F6: 198675496 | G6: 198849496 | H6: 197005196 | I6: 198055387 | J6: 198316568 | K6: 198055387 | L6: 197778001 | M6: =L6-C6 -> -1011495 | N6: 活散户
A7: 摩根士丹利 MS | B7: PB | C7: 156496714 | D7: 156888215 | E7: 156684015 | F7: 156684015 | G7: 156760015 | H7: 167280505 | I7: 157088593 | J7: 162498281 | K7: 157760090 | L7: 157075417 | M7: =L7-C7 -> 578703 | N7: 活PB
A8: 中金 CICC | B8: 中资投行 | C8: 152102420 | D8: 152102420 | E8: 152102420 | F8: 152102420 | G8: 152102420 | H8: 152144420 | I8: 152144420 | J8: 152144420 | K8: 152102420 | L8: 152102420 | M8: =L8-C8 -> 0 | N8: 死冻结
A9: 高盛 GS | B9: PB | C9: 101521300 | D9: 101521300 | E9: 101521300 | F9: 101521300 | G9: 101521300 | H9: 101521300 | I9: 102427172 | J9: 101521300 | K9: 102155154 | L9: 101528107 | M9: =L9-C9 -> 6807 | N9: 死冻结
A10: 花旗 Citi | B10: 托管 | C10: 98754794 | D10: 99256316 | E10: 91950242 | F10: 91950242 | G10: 86467733 | H10: 74417490 | I10: 79824121 | J10: 87878570 | K10: 92491656 | L10: 95129708 | M10: =L10-C10 -> -3625086 | N10: 活(反转买家)
A11: 南向 A00004 | B11: 南向 | C11: 96626355 | D11: 95774355 | E11: 95504355 | F11: 95504355 | G11: 95894355 | H11: 92062318 | I11: 91800318 | J11: 91866318 | K11: 91594318 | L11: 91856318 | M11: =L11-C11 -> -4770037 | N11: 南向
A12: 南向 A00003 | B12: 南向 | C12: 58724000 | D12: 58252000 | E12: 58946000 | F12: 58946000 | G12: 59994000 | H12: 56984000 | I12: 56362000 | J12: 57096000 | K12: 55544000 | L12: 54142000 | M12: =L12-C12 -> -4582000 | N12: 南向
A13: 华泰 Huatai | B13: 中资券商 | C13: 44845454 | D13: 44851454 | E13: 44831454 | F13: 44831454 | G13: 44835454 | H13: 44740522 | I13: 45644522 | J13: 48799373 | K13: 49451373 | L13: 49671373 | M13: =L13-C13 -> 4825919 | N13: ★持续买家
A14: 中银香港 | B14: 托管 | C14: 34100140 | D14: 34066140 | E14: 34126140 | F14: 34126140 | G14: 34296140 | H14: 33202140 | I14: 31844140 | J14: 31742140 | K14: 31156140 | L14: 31050140 | M14: =L14-C14 -> -3050000 | N14: 半死
A15: 法巴 BNP | B15: PB | C15: 8512535 | D15: 7920535 | E15: 7857704 | F15: 7857704 | G15: 8976292 | H15: 9268866 | I15: 8801066 | J15: 7792998 | K15: 8244796 | L15: 7002003 | M15: =L15-C15 -> -1510532 | N15: 活
A16: UBS | B16: PB | C16: 5885669 | D16: 5028669 | E16: 5477776 | F16: 5477776 | G16: 5239776 | H16: 6405776 | I16: 6366776 | J16: 6350776 | K16: 5689514 | L16: 5293513 | M16: =L16-C16 -> -592156 | N16: 活
... A19: 摩根大通 JPM | B19: PB | C19: 744000 | D19: 430000 | E19: 430000 | F19: 430000 | G19: 3860000 | H19: 0 | I19: 0 | J19: 0 | K19: 0 | L19: 0 | M19: =L19-C19 -> -744000 | N19: 噪声
A20: *JPM 8/27脉冲8/29归零=典型交收噪声,勿单日过度解读
A22: 汇总指标
A23: 指标 | C23: 8/22 | D23: 8/24 | E23: 8/25 | F23: 8/26 | G23: 8/27 | H23: 8/29 | I23: 8/31 | J23: 9/3 | K23: 9/8 | L23: 9/9 | M23: 净变动
A24: 已发行(约) | C24: 1401000000
A25: 南向持股 % | C25: =(C11+C12)/$C$24 -> 0.11088534 | D25: =(D11+D12)/$C$24 -> 0.1099403 | E25: =(E11+E12)/$C$24 -> 0.11024294 | F25: =(F11+F12)/$C$24 -> 0.11024294 | G25: =(G11+G12)/$C$24 -> 0.11126935 | H25: =(H11+H12)/$C$24 -> 0.10638567 | I25: =(I11+I12)/$C$24 -> 0.10575469 | J25: =(J11+J12)/$C$24 -> 0.10632571 | ... L25: =(L11+L12)/$C$24 -> 0.10421008 | M25: =L25-C25 -> -0.0066752584
A26: 前5大集中度 % | C26: =SUM(C5:C9)/$C$24 -> 0.63932378 | D26: =SUM(D5:D9)/$C$24 -> 0.64079117 | E26: =SUM(E5:E9)/$C$24 -> 0.64560337 | F26: =SUM(F5:F9)/$C$24 -> 0.64560337 | G26: =SUM(G5:G9)/$C$24 -> 0.64408133 | H26: =SUM(H5:H9)/$C$24 -> 0.6580525 | I26: =SUM(I5:I9)/$C$24 -> 0.65012606 | J26: =SUM(J5:J9)/$C$24 -> 0.65555703 | ... L26: =SUM(L5:L9)/$C$24 -> 0.64937901
A28: 逐日净流向(按类别,单位:万股)
A29: 类别 | B29: 8/24 | C29: 8/25 | D29: 8/26 | E29: 8/27 | F29: 8/29 | G29: 8/31 | H29: 9/3 | I29: 9/8 | J29: 9/9 | K29: 累计Δ | L29: 角色
A30: ★南向(A3+A4) | B30: =((D11+D12)-(C11+C12))/10000 -> -132.4 | C30: =((E11+E12)-(D11+D12))/10000 -> 42.4 | D30: =((F11+F12)-(E11+E12))/10000 -> 0 | E30: =((G11+G12)-(F11+F12))/10000 -> 143.8 | F30: =((H11+H12)-(G11+G12))/10000 -> -684.2037 | G30: =((I11+I12)-(H11+H12))/10000 -> -88.4 | H30: =((J11+J12)-(I11+I12))/10000 -> 80 | I30: =((K11+K12)-(J11+J12))/10000 -> -182.4 | J30: =((L11+L12)-(K11+K12))/10000 -> -114 | K30: =((L11+L12)-(C11+C12))/10000 -> -935.2037 | L30: swing因子
A31: ★华泰 | B31: =((D13)-(C13))/10000 -> 0.6 | C31: =((E13)-(D13))/10000 -> -2 | D31: =((F13)-(E13))/10000 -> 0 | E31: =((G13)-(F13))/10000 -> 0.4 | F31: =((H13)-(G13))/10000 -> -9.4932 | G31: =((I13)-(H13))/10000 -> 90.4 | H31: =((J13)-(I13))/10000 -> 315.4851 | I31: =((K13)-(J13))/10000 -> 65.2 | J31: =((L13)-(K13))/10000 -> 22 | K31: =((L13)-(C13))/10000 -> 482.5919 | L31: 持续买家
A32: 花旗Citi | B32: =((D10)-(C10))/10000 -> 50.1522 | C32: =((E10)-(D10))/10000 -> -730.6074 | D32: =((F10)-(E10))/10000 -> 0 | E32: =((G10)-(F10))/10000 -> -548.2509 | F32: =((H10)-(G10))/10000 -> -1205.0243 | G32: =((I10)-(H10))/10000 -> 540.6631 | H32: =((J10)-(I10))/10000 -> 805.4449 | I32: =((K10)-(J10))/10000 -> 461.3086 | J32: =((L10)-(K10))/10000 -> 263.8052 | K32: =((L10)-(C10))/10000 -> -362.5086 | L32: 卖压→反转
A33: PB活跃(MS/UBS/BNP/ML/JPM) | B33: =((D7+D15+D16+D18+D19)-(C7+C15+C16+C18+C19))/10000 -> -140.9319 | C33: =((E7+E15+E16+E18+E19)-(D7+D15+D16+D18+D19))/10000 -> 9.7896 | D33: =((F7+F15+F16+F18+F19)-(E7+E15+E16+E18+E19))/10000 -> 0 | E33: =((G7+G15+G16+G18+G19)-(F7+F15+F16+F18+F19))/10000 -> 439.2588 | F33: =((H7+H15+H16+H18+H19)-(G7+G15+G16+G18+G19))/10000 -> 1296.9064 | G33: =((I7+I15+I16+I18+I19)-(H7+H15+H16+H18+H19))/10000 -> -1080.9543 | H33: =((J7+J15+J16+J18+J19)-(I7+I15+I16+I18+I19))/10000 -> -41.1549 | I33: =((K7+K15+K16+K18+K19)-(J7+J15+J16+J18+J19))/10000 -> -336.7655 | J33: =((L7+L15+L16+L18+L19)-(K7+K15+K16+K18+K19))/10000 -> -212.7467 | K33: =((L7+L15+L16+L18+L19)-(C7+C15+C16+C18+C19))/10000 -> -66.5985 | L33: 对冲/机构
A34: 散户(Futu+IB) | B34: =((D6+D17)-(C6+C17))/10000 -> -18 | C34: =((E6+E17)-(D6+D17))/10000 -> -15.6 | D34: =((F6+F17)-(E6+E17))/10000 -> 0 | E34: =((G6+G17)-(F6+F17))/10000 -> 29.2 | F34: =((H6+H17)-(G6+G17))/10000 -> -100.6751 | G34: =((I6+I17)-(H6+H17))/10000 -> 124.4191 | H34: =((J6+J17)-(I6+I17))/10000 -> 0.1181 | I34: =((K6+K17)-(J6+J17))/10000 -> 62.8819 | J34: =((L6+L17)-(K6+K17))/10000 -> 12.0614 | K34: =((L6+L17)-(C6+C17))/10000 -> 94.4054 | L34: 情绪
A35: 汇丰HSBC(托管) | B35: =((D5)-(C5))/10000 -> 207.2312 | C35: =((E5)-(D5))/10000 -> 665.2098 | D35: =((F5)-(E5))/10000 -> 0 | E35: =((G5)-(F5))/10000 -> -238.2377 | F35: =((H5)-(G5))/10000 -> 1085.5419 | G35: =((I5)-(H5))/10000 -> -286.9089 | H35: =((J5)-(I5))/10000 -> 284.3786 | I35: =((K5)-(J5))/10000 -> -1.7569 | J35: =((L5)-(K5))/10000 -> -264.1206 | K35: =((L5)-(C5))/10000 -> 1451.3374 | L35: 混合口径
A37: 股价与阶段(HK$,约估)
A38: 日期 | B38: 8/22 | C38: 8/24 | D38: 8/25 | E38: 8/26 | F38: 8/27 | G38: 8/29 | H38: 8/31 | I38: 9/3 | J38: 9/8 | K38: 9/9
A39: 收盘价(约) | B39: 9.3 | C39: 9.3 | D39: 9.2 | E39: 9.1 | F39: 8.9 | G39: 8.7 | H39: 8.55 | I39: 8.4 | J39: 8.95 | K39: 9.34
A40: 注:8/22–9/8价格为约估;9/9=9.34(实测,+4.42%)。仅用于示意量价关系
A42: 完整弧线结论
A43: 阶段①(8/25–8/29 派发):花旗大户狂减、南向净卖、散户出货,股价下跌,市场不奖励中报。
A44: 阶段②(8/31–9/3 卖压衰竭):花旗从'狂减'转为'回补'(全周约+1300万),南向止跌企稳,最凶的抛售停止。
A45: 阶段③(9/3–9/9 买盘扩散):华泰持续加仓(累计+483万)、盈透+196万、ML+172万,花旗从卖方彻底转为买方,量价开始配合上行。
A46: ★到位:①最大卖压出清并回补 ②华泰确立为持续买家 ③买盘从单点扩散到多线 ④9/9放量+4.42%站上9.34,PE约10.2x仍低于中性锚定11.8x。
A47: ★未到位:南向(内地资金)仍净流出(11.09%→10.42%,累计减约938万股),是唯一还在拖后腿的主力。
...

Sheet 估值与情景
A1: 赤子城科技 (9911.HK) — 估值与情景锚定
A2: 绿字=引自利润表/假设页｜EV=市值−净现金｜锚定采用「核心经调整」口径(剔除出售/重估一次性收益)
A4: 一、当前市场快照
A5: 当前股价 (HK$) | B5: =假设与输入!$B$7 -> 9
A6: 摊薄股数 (百万股) | B6: =假设与输入!$B$8 -> 1350
A7: 市值 (HK$mm) | B7: =假设与输入!$B$7*假设与输入!$B$8 -> 12150
A8: 市值 (US$mm) | B8: =假设与输入!$B$7*假设与输入!$B$8/假设与输入!$B$6 -> 1557.6923
A9: 净现金 (US$mm) | B9: =假设与输入!$B$9 -> 497
A10: 企业价值 EV (US$mm) | B10: =假设与输入!$B$7*假设与输入!$B$8/假设与输入!$B$6-假设与输入!$B$9 -> 1060.6923
A11: 每股净现金 (HK$) | B11: =假设与输入!$B$9/假设与输入!$B$8*假设与输入!$B$6 -> 2.8715556
A12: 净现金占市值 % | B12: =假设与输入!$B$9/(假设与输入!$B$7*假设与输入!$B$8/假设与输入!$B$6) -> 0.31906173
A14: 二、当前股价隐含倍数
A15: 指标 | B15: FY2026E | C15: FY2027E
A16: 市销率 P/S | B16: =(假设与输入!$B$7*假设与输入!$B$8/假设与输入!$B$6)/利润表!G7 -> 1.1976122 | C16: =(假设与输入!$B$7*假设与输入!$B$8/假设与输入!$B$6)/利润表!H7 -> 0.96702278
A17: 市盈率 P/E (报告归母) | B17: =(假设与输入!$B$7*假设与输入!$B$8/假设与输入!$B$6)/利润表!G27 -> 9.0367024 | C17: =(假设与输入!$B$7*假设与输入!$B$8/假设与输入!$B$6)/利润表!H27 -> 8.2916678
A18: 市盈率 P/E (核心归母,剔一次性) | B18: =(假设与输入!$B$7*假设与输入!$B$8/假设与输入!$B$6)/利润表!G34 -> 11.740753 | C18: =(假设与输入!$B$7*假设与输入!$B$8/假设与输入!$B$6)/利润表!H34 -> 8.2916678
A19: 市盈率 P/E (核心经调整) | B19: =(假设与输入!$B$7*假设与输入!$B$8/假设与输入!$B$6)/利润表!G35 -> 9.9575065 | C19: =(假设与输入!$B$7*假设与输入!$B$8/假设与输入!$B$6)/利润表!H35 -> 7.2588431
A20: EV/EBITDA (核心经调整) | B20: =(假设与输入!$B$7*假设与输入!$B$8/假设与输入!$B$6-假设与输入!$B$9)/利润表!G37 -> 5.8937666 | C20: =(假设与输入!$B$7*假设与输入!$B$8/假设与输入!$B$6-假设与输入!$B$9)/利润表!H37 -> 4.5014664
A22: 三、锚定价格 · 情景分析 (12个月)
A23: 方法 / 情景 | B23: 悲观 | C23: 中性 | D23: 乐观 | E23: 口径说明
A24: A. FY26E核心经调整归母 × P/E | B24: =利润表!$G$35*假设与输入!B40/假设与输入!$B$8*假设与输入!$B$6 -> 7.2307259 | C24: =利润表!$G$35*假设与输入!C40/假设与输入!$B$8*假设与输入!$B$6 -> 9.9422481 | D24: =利润表!$G$35*假设与输入!D40/假设与输入!$B$8*假设与输入!$B$6 -> 12.65377 | E24: 利润表G35 × PE26
A25: B. FY27E核心经调整归母 × P/E | B25: =利润表!$H$35*假设与输入!B41/假设与输入!$B$8*假设与输入!$B$6 -> 8.6790689 | C25: =利润表!$H$35*假设与输入!C41/假设与输入!$B$8*假设与输入!$B$6 -> 12.39867 | D25: =利润表!$H$35*假设与输入!D41/假设与输入!$B$8*假设与输入!$B$6 -> 16.118271 | E25: 利润表H35 × PE27
A26: C. FY27E核心经调整EBITDA × EV/EBITDA | B26: =(利润表!$H$37*假设与输入!B42+假设与输入!$B$9)/假设与输入!$B$8*假设与输入!$B$6 -> 9.67872 | C26: =(利润表!$H$37*假设与输入!C42+假设与输入!$B$9)/假设与输入!$B$8*假设与输入!$B$6 -> 13.082302 | D26: =(利润表!$H$37*假设与输入!D42+假设与输入!$B$9)/假设与输入!$B$8*假设与输入!$B$6 -> 16.485884 | E26: (H37×EV倍数+净现金)/股
A27: 锚定价 (三法平均) | B27: =AVERAGE(B24,B25,B26) -> 8.529505 | C27: =AVERAGE(C24,C25,C26) -> 11.80774 | D27: =AVERAGE(D24,D25,D26) -> 15.085975 | E27: 三法(A/B/C)均值
A28: 较当前股价上行空间 | B28: =B27/假设与输入!$B$7-1 -> -0.052277227 | C28: =C27/假设与输入!$B$7-1 -> 0.31197112 | D28: =D27/假设与输入!$B$7-1 -> 0.67621947
A30: 四、敏感性：FY27E核心经调整归母 × P/E → 股价(HK$)
A31: 核心经调整归母(US$mm) \ P/E | B31: 8 | C31: 10 | D31: 12 | E31: 14
A32: 190 | B32: =$A32*B$31/假设与输入!$B$8*假设与输入!$B$6 -> 8.7822222 | C32: =$A32*C$31/假设与输入!$B$8*假设与输入!$B$6 -> 10.977778 | D32: =$A32*D$31/假设与输入!$B$8*假设与输入!$B$6 -> 13.173333 | E32: =$A32*E$31/假设与输入!$B$8*假设与输入!$B$6 -> 15.368889
A33: 215 | B33: =$A33*B$32/假设与输入!$B$8*假设与输入!$B$6 -> 10.909472 | C33: =$A33*C$32/假设与输入!$B$8*假设与输入!$B$6 -> 13.63684 | D33: =$A33*D$32/假设与输入!$B$8*假设与输入!$B$6 -> 16.364207 | E33: =$A33*E$32/假设与输入!$B$8*假设与输入!$B$6 -> 19.091575
A34: 240 | B34: =$A34*B$33/假设与输入!$B$8*假设与输入!$B$6 -> 15.127801 | C34: =$A34*C$33/假设与输入!$B$8*假设与输入!$B$6 -> 18.909751 | D34: =$A34*D$33/假设与输入!$B$8*假设与输入!$B$6 -> 22.691701 | E34: =$A34*E$33/假设与输入!$B$8*假设与输入!$B$6 -> 26.473651
A35: 265 | B35: =$A35*B$34/假设与输入!$B$8*假设与输入!$B$6 -> 23.162344 | C35: =$A35*C$34/假设与输入!$B$8*假设与输入!$B$6 -> 28.95293 | D35: =$A35*D$34/假设与输入!$B$8*假设与输入!$B$6 -> 34.743515 | E35: =$A35*E$34/假设与输入!$B$8*假设与输入!$B$6 -> 40.534101
A36: 注：黄色区为大致落点；行=盈利假设(受营销费率驱动)，列=给予倍数。
A38: 五、卖方目标价参考 (供对照，非本模型输出)
A39: 机构 | B39: 目标价(HK$) | C39: 评级 | D39: 依据
A40: 中金 CICC | B40: 14.5 | C40: 跑赢行业 | D40: 14x 2026 Non-IFRS P/E；关注港股通重估
A41: 光大证券 | B41: 14.5 | C41: 买入 | D41: 首次覆盖(2025/12)
A42: 西牛证券 | B42: 13.2 | C42: 买入 | D42: 2025/11
A43: 花旗 Citi | B43: — | C43: 买入 | D43: 四重催化，首次覆盖
A44: 中泰证券 | B44: — | C44: 买入 | D44: FY26-28归母11.8/14.9/19.1亿元(RMB)
A45: 市场中枢(约) | B45: 13.5 | C45: — | D45: 区间约11.5–17.9；11家买入

Sheet 假设与输入
A1: 赤子城科技 (9911.HK) — 估值模型假设与输入
A2: 单位：百万美元(除标注外)｜蓝字=硬输入/情景杠杆(可改)｜黄底=关键假设｜数据基于公司公告与公开研报
A4: 一、汇率与市场输入
A5: 美元兑人民币 USD/CNY | B5: 7.15 | C5: 历史人民币口径折美元用（约数）
A6: 美元兑港元 USD/HKD | B6: 7.8 | C6: 联系汇率
A7: 当前股价 (HK$) | B7: 9 | C7: 2026年8月约8.6–9.3区间，请以实时为准
A8: 摊薄股数 (百万股) | B8: 1350 | C8: 中报摊薄加权约13.5亿；已发行约14.0亿
A9: 净现金 (百万美元) | B9: 497 | C9: 现金409.4+定存46.2+理财53.8-租赁负债12.5
A11: 二、分部收入增长假设 (同比)
B12: FY2026E | C12: FY2027E | D12: FY2028E
A13: 社交业务收入增速 | B13: 0.34 | C13: 0.22 | D13: 0.2
A14: 创新业务收入增速 | B14: 0.43 | C14: 0.38 | D14: 0.32
A16: 三、利润率与费用假设 (占收入%)
B17: FY2026E | C17: FY2027E | D17: FY2028E
A18: 毛利率 Gross margin | B18: 0.575 | C18: 0.57 | D18: 0.565 | F18: H1'26实际57.8%
A19: 销售及营销费用率 S&M | B19: 0.37 | C19: 0.355 | D19: 0.34 | F19: 据Sensor Tower:下载+100%但收入+45%,买量效率下滑→费率难快速回落,上调
A20: 研发费用率 R&D | B20: 0.05 | C20: 0.05 | D20: 0.05 | F20: H1'26实际5.1%
A21: 管理费用率 G&A | B21: 0.034 | C21: 0.033 | D21: 0.032 | F21: H1'26实际3.4%
A22: 其他经营净损益率 Other | B22: 0.018 | C22: 0.018 | D22: 0.018 | F22: 减值+其他净损失
A24: 四、线下项目假设 (百万美元)
B25: FY2026E | C25: FY2027E | D25: FY2028E
A26: 净财务收入 Net finance income | B26: 11 | C26: 13 | D26: 15
A27: 应占联营损益 Assoc. | B27: -7 | C27: -3 | D27: 0
A28: 所得税率 Tax rate | B28: 0.02 | C28: 0.02 | D28: 0.02
A29: 少数股东损益率 NCI %净利 | B29: 0.01 | C29: 0.01 | D29: 0.01
A30: 股份薪酬 SBC | B30: 24 | C30: 27 | D30: 29
A31: 折旧摊销 D&A | B31: 22 | C31: 25 | D31: 28
A33: 五、一次性项目 (仅FY2026, 百万美元)
A34: 出售附属公司收益 (NADA+Ditto) | B34: 29.9 | C34: NADA 17.3 + Ditto 12.5（H1已入账）
A35: 权益法重估收益(净) | B35: 9.8 | C35: NADA重估14.6 − 摊薄亏损4.8
A36: 一次性合计 | B36: =B34+B35 -> 39.7
A38: 六、估值倍数情景 (锚定用)
B39: 悲观 | C39: 中性 | D39: 乐观
A40: FY26E 核心经调整归母 P/E | B40: 8 | C40: 11 | D40: 14
A41: FY27E 核心经调整归母 P/E | B41: 7 | C41: 10 | D41: 13
A42: FY27E 核心经调整EBITDA EV/EBITDA | B42: 5 | C42: 7.5 | D42: 10
